{
 "cells": [
  {
   "cell_type": "code",
   "execution_count": 1,
   "metadata": {},
   "outputs": [
    {
     "name": "stderr",
     "output_type": "stream",
     "text": [
      "/Library/Frameworks/Python.framework/Versions/3.6/lib/python3.6/site-packages/ipykernel_launcher.py:1: RemovedInDjango20Warning: Importing from django.core.urlresolvers is deprecated in favor of django.urls.\n",
      "  \"\"\"Entry point for launching an IPython kernel.\n"
     ]
    }
   ],
   "source": [
    "from django.core.urlresolvers import reverse"
   ]
  },
  {
   "cell_type": "code",
   "execution_count": 2,
   "metadata": {},
   "outputs": [
    {
     "data": {
      "text/plain": [
       "'/blog/'"
      ]
     },
     "execution_count": 2,
     "metadata": {},
     "output_type": "execute_result"
    }
   ],
   "source": [
    "reverse('blog:post_list')"
   ]
  },
  {
   "cell_type": "code",
   "execution_count": 3,
   "metadata": {},
   "outputs": [
    {
     "ename": "ImproperlyConfigured",
     "evalue": "The included URLconf '10' does not appear to have any patterns in it. If you see valid patterns in the file then the issue is probably caused by a circular import.",
     "output_type": "error",
     "traceback": [
      "\u001b[0;31m---------------------------------------------------------------------------\u001b[0m",
      "\u001b[0;31mTypeError\u001b[0m                                 Traceback (most recent call last)",
      "\u001b[0;32m/Library/Frameworks/Python.framework/Versions/3.6/lib/python3.6/site-packages/django/urls/resolvers.py\u001b[0m in \u001b[0;36murl_patterns\u001b[0;34m(self)\u001b[0m\n\u001b[1;32m    406\u001b[0m         \u001b[0;32mtry\u001b[0m\u001b[0;34m:\u001b[0m\u001b[0;34m\u001b[0m\u001b[0m\n\u001b[0;32m--> 407\u001b[0;31m             \u001b[0miter\u001b[0m\u001b[0;34m(\u001b[0m\u001b[0mpatterns\u001b[0m\u001b[0;34m)\u001b[0m\u001b[0;34m\u001b[0m\u001b[0m\n\u001b[0m\u001b[1;32m    408\u001b[0m         \u001b[0;32mexcept\u001b[0m \u001b[0mTypeError\u001b[0m\u001b[0;34m:\u001b[0m\u001b[0;34m\u001b[0m\u001b[0m\n",
      "\u001b[0;31mTypeError\u001b[0m: 'int' object is not iterable",
      "\nDuring handling of the above exception, another exception occurred:\n",
      "\u001b[0;31mImproperlyConfigured\u001b[0m                      Traceback (most recent call last)",
      "\u001b[0;32m<ipython-input-3-25682772b612>\u001b[0m in \u001b[0;36m<module>\u001b[0;34m()\u001b[0m\n\u001b[0;32m----> 1\u001b[0;31m \u001b[0mreverse\u001b[0m\u001b[0;34m(\u001b[0m\u001b[0;34m'blog:post_detail'\u001b[0m\u001b[0;34m,\u001b[0m\u001b[0;36m10\u001b[0m\u001b[0;34m)\u001b[0m\u001b[0;34m\u001b[0m\u001b[0m\n\u001b[0m",
      "\u001b[0;32m/Library/Frameworks/Python.framework/Versions/3.6/lib/python3.6/site-packages/django/urls/base.py\u001b[0m in \u001b[0;36mreverse\u001b[0;34m(viewname, urlconf, args, kwargs, current_app)\u001b[0m\n\u001b[1;32m     58\u001b[0m             \u001b[0;31m# Lookup the name to see if it could be an app identifier.\u001b[0m\u001b[0;34m\u001b[0m\u001b[0;34m\u001b[0m\u001b[0m\n\u001b[1;32m     59\u001b[0m             \u001b[0;32mtry\u001b[0m\u001b[0;34m:\u001b[0m\u001b[0;34m\u001b[0m\u001b[0m\n\u001b[0;32m---> 60\u001b[0;31m                 \u001b[0mapp_list\u001b[0m \u001b[0;34m=\u001b[0m \u001b[0mresolver\u001b[0m\u001b[0;34m.\u001b[0m\u001b[0mapp_dict\u001b[0m\u001b[0;34m[\u001b[0m\u001b[0mns\u001b[0m\u001b[0;34m]\u001b[0m\u001b[0;34m\u001b[0m\u001b[0m\n\u001b[0m\u001b[1;32m     61\u001b[0m                 \u001b[0;31m# Yes! Path part matches an app in the current Resolver.\u001b[0m\u001b[0;34m\u001b[0m\u001b[0;34m\u001b[0m\u001b[0m\n\u001b[1;32m     62\u001b[0m                 \u001b[0;32mif\u001b[0m \u001b[0mcurrent_ns\u001b[0m \u001b[0;32mand\u001b[0m \u001b[0mcurrent_ns\u001b[0m \u001b[0;32min\u001b[0m \u001b[0mapp_list\u001b[0m\u001b[0;34m:\u001b[0m\u001b[0;34m\u001b[0m\u001b[0m\n",
      "\u001b[0;32m/Library/Frameworks/Python.framework/Versions/3.6/lib/python3.6/site-packages/django/urls/resolvers.py\u001b[0m in \u001b[0;36mapp_dict\u001b[0;34m(self)\u001b[0m\n\u001b[1;32m    346\u001b[0m         \u001b[0mlanguage_code\u001b[0m \u001b[0;34m=\u001b[0m \u001b[0mget_language\u001b[0m\u001b[0;34m(\u001b[0m\u001b[0;34m)\u001b[0m\u001b[0;34m\u001b[0m\u001b[0m\n\u001b[1;32m    347\u001b[0m         \u001b[0;32mif\u001b[0m \u001b[0mlanguage_code\u001b[0m \u001b[0;32mnot\u001b[0m \u001b[0;32min\u001b[0m \u001b[0mself\u001b[0m\u001b[0;34m.\u001b[0m\u001b[0m_app_dict\u001b[0m\u001b[0;34m:\u001b[0m\u001b[0;34m\u001b[0m\u001b[0m\n\u001b[0;32m--> 348\u001b[0;31m             \u001b[0mself\u001b[0m\u001b[0;34m.\u001b[0m\u001b[0m_populate\u001b[0m\u001b[0;34m(\u001b[0m\u001b[0;34m)\u001b[0m\u001b[0;34m\u001b[0m\u001b[0m\n\u001b[0m\u001b[1;32m    349\u001b[0m         \u001b[0;32mreturn\u001b[0m \u001b[0mself\u001b[0m\u001b[0;34m.\u001b[0m\u001b[0m_app_dict\u001b[0m\u001b[0;34m[\u001b[0m\u001b[0mlanguage_code\u001b[0m\u001b[0;34m]\u001b[0m\u001b[0;34m\u001b[0m\u001b[0m\n\u001b[1;32m    350\u001b[0m \u001b[0;34m\u001b[0m\u001b[0m\n",
      "\u001b[0;32m/Library/Frameworks/Python.framework/Versions/3.6/lib/python3.6/site-packages/django/urls/resolvers.py\u001b[0m in \u001b[0;36m_populate\u001b[0;34m(self)\u001b[0m\n\u001b[1;32m    286\u001b[0m         \u001b[0mapps\u001b[0m \u001b[0;34m=\u001b[0m \u001b[0;34m{\u001b[0m\u001b[0;34m}\u001b[0m\u001b[0;34m\u001b[0m\u001b[0m\n\u001b[1;32m    287\u001b[0m         \u001b[0mlanguage_code\u001b[0m \u001b[0;34m=\u001b[0m \u001b[0mget_language\u001b[0m\u001b[0;34m(\u001b[0m\u001b[0;34m)\u001b[0m\u001b[0;34m\u001b[0m\u001b[0m\n\u001b[0;32m--> 288\u001b[0;31m         \u001b[0;32mfor\u001b[0m \u001b[0mpattern\u001b[0m \u001b[0;32min\u001b[0m \u001b[0mreversed\u001b[0m\u001b[0;34m(\u001b[0m\u001b[0mself\u001b[0m\u001b[0;34m.\u001b[0m\u001b[0murl_patterns\u001b[0m\u001b[0;34m)\u001b[0m\u001b[0;34m:\u001b[0m\u001b[0;34m\u001b[0m\u001b[0m\n\u001b[0m\u001b[1;32m    289\u001b[0m             \u001b[0;32mif\u001b[0m \u001b[0misinstance\u001b[0m\u001b[0;34m(\u001b[0m\u001b[0mpattern\u001b[0m\u001b[0;34m,\u001b[0m \u001b[0mRegexURLPattern\u001b[0m\u001b[0;34m)\u001b[0m\u001b[0;34m:\u001b[0m\u001b[0;34m\u001b[0m\u001b[0m\n\u001b[1;32m    290\u001b[0m                 \u001b[0mself\u001b[0m\u001b[0;34m.\u001b[0m\u001b[0m_callback_strs\u001b[0m\u001b[0;34m.\u001b[0m\u001b[0madd\u001b[0m\u001b[0;34m(\u001b[0m\u001b[0mpattern\u001b[0m\u001b[0;34m.\u001b[0m\u001b[0mlookup_str\u001b[0m\u001b[0;34m)\u001b[0m\u001b[0;34m\u001b[0m\u001b[0m\n",
      "\u001b[0;32m/Library/Frameworks/Python.framework/Versions/3.6/lib/python3.6/site-packages/django/utils/functional.py\u001b[0m in \u001b[0;36m__get__\u001b[0;34m(self, instance, cls)\u001b[0m\n\u001b[1;32m     33\u001b[0m         \u001b[0;32mif\u001b[0m \u001b[0minstance\u001b[0m \u001b[0;32mis\u001b[0m \u001b[0;32mNone\u001b[0m\u001b[0;34m:\u001b[0m\u001b[0;34m\u001b[0m\u001b[0m\n\u001b[1;32m     34\u001b[0m             \u001b[0;32mreturn\u001b[0m \u001b[0mself\u001b[0m\u001b[0;34m\u001b[0m\u001b[0m\n\u001b[0;32m---> 35\u001b[0;31m         \u001b[0mres\u001b[0m \u001b[0;34m=\u001b[0m \u001b[0minstance\u001b[0m\u001b[0;34m.\u001b[0m\u001b[0m__dict__\u001b[0m\u001b[0;34m[\u001b[0m\u001b[0mself\u001b[0m\u001b[0;34m.\u001b[0m\u001b[0mname\u001b[0m\u001b[0;34m]\u001b[0m \u001b[0;34m=\u001b[0m \u001b[0mself\u001b[0m\u001b[0;34m.\u001b[0m\u001b[0mfunc\u001b[0m\u001b[0;34m(\u001b[0m\u001b[0minstance\u001b[0m\u001b[0;34m)\u001b[0m\u001b[0;34m\u001b[0m\u001b[0m\n\u001b[0m\u001b[1;32m     36\u001b[0m         \u001b[0;32mreturn\u001b[0m \u001b[0mres\u001b[0m\u001b[0;34m\u001b[0m\u001b[0m\n\u001b[1;32m     37\u001b[0m \u001b[0;34m\u001b[0m\u001b[0m\n",
      "\u001b[0;32m/Library/Frameworks/Python.framework/Versions/3.6/lib/python3.6/site-packages/django/urls/resolvers.py\u001b[0m in \u001b[0;36murl_patterns\u001b[0;34m(self)\u001b[0m\n\u001b[1;32m    412\u001b[0m                 \u001b[0;34m\"the issue is probably caused by a circular import.\"\u001b[0m\u001b[0;34m\u001b[0m\u001b[0m\n\u001b[1;32m    413\u001b[0m             )\n\u001b[0;32m--> 414\u001b[0;31m             \u001b[0;32mraise\u001b[0m \u001b[0mImproperlyConfigured\u001b[0m\u001b[0;34m(\u001b[0m\u001b[0mmsg\u001b[0m\u001b[0;34m.\u001b[0m\u001b[0mformat\u001b[0m\u001b[0;34m(\u001b[0m\u001b[0mname\u001b[0m\u001b[0;34m=\u001b[0m\u001b[0mself\u001b[0m\u001b[0;34m.\u001b[0m\u001b[0murlconf_name\u001b[0m\u001b[0;34m)\u001b[0m\u001b[0;34m)\u001b[0m\u001b[0;34m\u001b[0m\u001b[0m\n\u001b[0m\u001b[1;32m    415\u001b[0m         \u001b[0;32mreturn\u001b[0m \u001b[0mpatterns\u001b[0m\u001b[0;34m\u001b[0m\u001b[0m\n\u001b[1;32m    416\u001b[0m \u001b[0;34m\u001b[0m\u001b[0m\n",
      "\u001b[0;31mImproperlyConfigured\u001b[0m: The included URLconf '10' does not appear to have any patterns in it. If you see valid patterns in the file then the issue is probably caused by a circular import."
     ]
    }
   ],
   "source": [
    "reverse('blog:post_detail', args=[10])"
   ]
  },
  {
   "cell_type": "code",
   "execution_count": null,
   "metadata": {
    "collapsed": true
   },
   "outputs": [],
   "source": []
  }
 ],
 "metadata": {
  "kernelspec": {
   "display_name": "Django Shell-Plus",
   "language": "python",
   "name": "django_extensions"
  },
  "language_info": {
   "codemirror_mode": {
    "name": "ipython",
    "version": 3
   },
   "file_extension": ".py",
   "mimetype": "text/x-python",
   "name": "python",
   "nbconvert_exporter": "python",
   "pygments_lexer": "ipython3",
   "version": "3.6.2"
  }
 },
 "nbformat": 4,
 "nbformat_minor": 2
}
